Workbook

Sheet Read Me
B2: RETAIL SALES PERFORMANCE ANALYSIS
B3: End-to-End Excel Analytics Project | US Superstore Retail Dataset (2014-2017)
B6: PROJECT OVERVIEW
B7: This workbook is a complete, production-style analytics deliverable built on a US retail
B8: (Superstore-style) transactional dataset of 1,000 order line items spanning 2014-2017.
B9: It covers data cleaning, feature engineering, KPI calculation, pivot-style analysis,
B10: a KPI dashboard, 40 answered business questions, and strategic recommendations.
B12: HOW TO NAVIGATE THIS WORKBOOK
B14: Sheet | C14: Contents
B15: Read Me | C15: This page - project navigation and summary.
B16: Data Dictionary | C16: Column-by-column definitions, data types, and business meaning.
B17: Cleaning Log | C17: Data quality checklist, checks performed, and results.
B18: Raw Data | C18: Original, unmodified source data (reference / audit trail).
B19: Enriched Data | C19: Cleaned data + 14 engineered features, live Excel formulas, structured as a Table.
B20: Summary Tables | C20: Pivot-style SUMIFS/COUNTIFS/AVERAGEIFS breakdowns by every key dimension.
B21: KPI Dashboard | C21: Executive KPI scorecard with charts, built entirely from formulas.
B22: Business Questions | C22: 40 business questions answered with figures, method, and interpretation.
B23: Insights & Recommendations | C23: 25+ data-driven insights and consulting-style strategic recommendations.
B25: AUTHOR / TOOLING
B26: Built with Microsoft Excel formulas (SUMIFS, COUNTIFS, AVERAGEIFS, nested IF,
B27: INDEX/MATCH). No macros. No external data connections. Fully self-contained.

Sheet Data Dictionary
A1: DATA DICTIONARY
A2: Column-level definitions for the source dataset (as delivered, before feature engineering)
A4: Column | B4: Data Type | C4: Business Meaning | D4: Data Quality Notes | E4: Analytical Importance
A5: Row ID | B5: Integer (Key) | C5: Sequential line-item identifier for the extract. | D5: Unique, no duplicates, no nulls. | E5: Technical key only; not used in analysis.
A6: Order ID | B6: Text (Composite Key) | C6: Groups line items into a single customer order (format: REGION-YEAR-#####). | D6: 1,000 rows roll up to 479 distinct orders (avg 2.1 items/order). | E6: Basis for Average Order Value and basket-size analysis.
A7: Order Date | B7: Date | C7: Date the customer placed the order. | D7: Range 2014-01-04 to 2017-12-30. No future/invalid dates. | E7: Drives all time-series, seasonality and YoY analysis.
A8: Ship Date | B8: Date | C8: Date the order was shipped/fulfilled. | D8: Always on/after Order Date (0 violations found). | E8: Basis for Shipping Delay / fulfilment KPI.
A9: Ship Mode | B9: Categorical | C9: Delivery service level chosen (Standard/Second/First Class, Same Day). | D9: 4 clean categories, no blanks. | E9: Links delivery cost/speed to profitability.
A10: Customer ID | B10: Text (Key) | C10: Unique identifier per customer. | D10: 362 unique customers across 1,000 line items. | E10: Basis for customer segmentation, repeat-purchase analysis.
A11: Customer Name | B11: Text | C11: Customer's display name. | D11: Free text; consistent casing. | E11: Used for top-customer ranking; not a join key (use Customer ID).
A12: Segment | B12: Categorical | C12: Customer type: Consumer, Corporate, Home Office. | D12: 3 clean categories. | E12: Core segmentation dimension for revenue & margin.
A13: Country | B13: Categorical | C13: Country of the shipping address. | D13: Single value: United States. Low analytical value, kept for completeness. | E13: Confirms single-market dataset.
A14: City | B14: Categorical | C14: City of the shipping address. | D14: 174 distinct cities; free text, consistent casing. | E14: Granular geo drill-down.
A15: State | B15: Categorical | C15: US state of the shipping address. | D15: 40 of 50 states represented. | E15: Primary geographic reporting dimension.
... A25: Profit | B25: Currency (float) | C25: Net profit for the line item, after cost and discount, in USD. | D25: Range includes negatives (186 loss-making lines = 18.6% of rows). | E25: Primary profitability KPI input; negatives are genuine business signal, not errors.

Sheet Cleaning Log
A1: DATA CLEANING & QUALITY ASSURANCE LOG
A2: Every check below was run programmatically against the full 1,000-row source extract.
A4: # | B4: Check Performed | C4: Method | D4: Result | E4: Action Taken / Status
A5: 1 | B5: Missing / blank values | C5: ISBLANK / COUNTBLANK across all 21 columns | D5: 0 missing values found in any column | E5: No action needed - dataset is complete
A6: 2 | B6: Full-row duplicates | C6: Row-level duplicate comparison across all columns | D6: 0 duplicate rows found | E6: No action needed
A7: 3 | B7: Duplicate technical key (Row ID) | C7: Uniqueness check on Row ID | D7: 0 duplicates - all 1,000 IDs unique | E7: No action needed
A8: 4 | B8: Date validity (Order Date, Ship Date) | C8: Range check: valid calendar dates, not in the future | D8: All dates valid; range 2014-01-04 to 2018-01-05 | E8: No action needed
A9: 5 | B9: Logical date sequence | C9: Ship Date >= Order Date for every row | D9: 0 violations - shipping never precedes ordering | E9: No action needed
A10: 6 | B10: Text formatting - extra spaces | C10: TRIM() comparison on all text columns | D10: No leading/trailing space issues detected | E10: TRIM() applied defensively in Enriched Data as best practice
A11: 7 | B11: Case consistency | C11: Spot-check of categorical fields (Category, Region, Segment, etc.) | D11: Consistent title-case across all categorical fields | E11: No action needed
A12: 8 | B12: Categorical domain check | C12: Distinct-value count per categorical column | D12: Category (3), Sub-Category (17), Region (4), Segment (3), Ship Mode (4) - all clean, expected values | E12: No action needed
A13: 9 | B13: Numeric range - Sales | C13: MIN/MAX bounds check | D13: Range $1.08 - $8,159.95; no zero or negative sales | E13: No action needed
A14: 10 | B14: Numeric range - Quantity | C14: MIN/MAX bounds check | D14: Range 1-14 units; no zero/negative quantities | E14: No action needed
A15: 11 | B15: Numeric range - Discount | C15: MIN/MAX bounds check (expected 0-1 as decimal fraction) | D15: Range 0%-80%; correctly stored as decimal | E15: No action needed - confirmed NOT to reformat as whole numbers
... A19: 15 | B19: Referential consistency | C19: Customer ID <-> Customer Name and Product ID <-> Product Name checked 1:1 | D19: No conflicting name-to-ID mappings found | E19: No action needed
A21: CONCLUSION
A22: The source extract is already of high analytical quality (0 nulls, 0 duplicates, valid date logic). This is common for curated portfolio/training datasets. Cleaning effort therefore focused on validation, documentation, and defensive formatting (TRIM/PROPER safeguards) rather than remediation - exactly the audit trail a stakeholder or hiring manager expects to see before trusting downstream KPIs.

Sheet Raw Data
A1: Row ID | B1: Order ID | C1: Order Date | D1: Ship Date | E1: Ship Mode | F1: Customer ID | G1: Customer Name | H1: Segment | I1: Country | J1: City | K1: State | L1: Postal Code | M1: Region | N1: Product ID | O1: Category | P1: Sub-Category | Q1: Product Name | R1: Sales | S1: Quantity | T1: Discount | U1: Profit
A2: 1 | B2: CA-2016-152156 | C2: 42682 | D2: 42685 | E2: Second Class | F2: CG-12520 | G2: Claire Gute | H2: Consumer | I2: United States | J2: Henderson | K2: Kentucky | L2: 42420 | M2: South | N2: FUR-BO-10001798 | O2: Furniture | P2: Bookcases | Q2: Bush Somerset Collection Bookcase | R2: 261.96 | S2: 2 | T2: 0 | U2: 41.9136
A3: 2 | B3: CA-2016-152156 | C3: 42682 | D3: 42685 | E3: Second Class | F3: CG-12520 | G3: Claire Gute | H3: Consumer | I3: United States | J3: Henderson | K3: Kentucky | L3: 42420 | M3: South | N3: FUR-CH-10000454 | O3: Furniture | P3: Chairs | Q3: Hon Deluxe Fabric Upholstered Stacking Chairs, Rounded Back | R3: 731.94 | S3: 3 | T3: 0 | U3: 219.582
A4: 3 | B4: CA-2016-138688 | C4: 42533 | D4: 42537 | E4: Second Class | F4: DV-13045 | G4: Darrin Van Huff | H4: Corporate | I4: United States | J4: Los Angeles | K4: California | L4: 90036 | M4: West | N4: OFF-LA-10000240 | O4: Office Supplies | P4: Labels | Q4: Self-Adhesive Address Labels for Typewriters by Universal | R4: 14.62 | S4: 2 | T4: 0 | U4: 6.8714
A5: 4 | B5: US-2015-108966 | C5: 42288 | D5: 42295 | E5: Standard Class | F5: SO-20335 | G5: Sean O'Donnell | H5: Consumer | I5: United States | J5: Fort Lauderdale | K5: Florida | L5: 33311 | M5: South | N5: FUR-TA-10000577 | O5: Furniture | P5: Tables | Q5: Bretford CR4500 Series Slim Rectangular Table | R5: 957.5775 | S5: 5 | T5: 0.45 | U5: -383.031
A6: 5 | B6: US-2015-108966 | C6: 42288 | D6: 42295 | E6: Standard Class | F6: SO-20335 | G6: Sean O'Donnell | H6: Consumer | I6: United States | J6: Fort Lauderdale | K6: Florida | L6: 33311 | M6: South | N6: OFF-ST-10000760 | O6: Office Supplies | P6: Storage | Q6: Eldon Fold 'N Roll Cart System | R6: 22.368 | S6: 2 | T6: 0.2 | U6: 2.5164
A7: 6 | B7: CA-2014-115812 | C7: 41799 | D7: 41804 | E7: Standard Class | F7: BH-11710 | G7: Brosina Hoffman | H7: Consumer | I7: United States | J7: Los Angeles | K7: California | L7: 90032 | M7: West | N7: FUR-FU-10001487 | O7: Furniture | P7: Furnishings | Q7: Eldon Expressions Wood and Plastic Desk Accessories, Cherry Wood | R7: 48.86 | S7: 7 | T7: 0 | U7: 14.1694
A8: 7 | B8: CA-2014-115812 | C8: 41799 | D8: 41804 | E8: Standard Class | F8: BH-11710 | G8: Brosina Hoffman | H8: Consumer | I8: United States | J8: Los Angeles | K8: California | L8: 90032 | M8: West | N8: OFF-AR-10002833 | O8: Office Supplies | P8: Art | Q8: Newell 322 | R8: 7.28 | S8: 4 | T8: 0 | U8: 1.9656
A9: 8 | B9: CA-2014-115812 | C9: 41799 | D9: 41804 | E9: Standard Class | F9: BH-11710 | G9: Brosina Hoffman | H9: Consumer | I9: United States | J9: Los Angeles | K9: California | L9: 90032 | M9: West | N9: TEC-PH-10002275 | O9: Technology | P9: Phones | Q9: Mitel 5320 IP Phone VoIP phone | R9: 907.152 | S9: 6 | T9: 0.2 | U9: 90.7152
A10: 9 | B10: CA-2014-115812 | C10: 41799 | D10: 41804 | E10: Standard Class | F10: BH-11710 | G10: Brosina Hoffman | H10: Consumer | I10: United States | J10: Los Angeles | K10: California | L10: 90032 | M10: West | N10: OFF-BI-10003910 | O10: Office Supplies | P10: Binders | Q10: DXL Angle-View Binders with Locking Rings by Samsill | R10: 18.504 | S10: 3 | T10: 0.2 | U10: 5.7825
A11: 10 | B11: CA-2014-115812 | C11: 41799 | D11: 41804 | E11: Standard Class | F11: BH-11710 | G11: Brosina Hoffman | H11: Consumer | I11: United States | J11: Los Angeles | K11: California | L11: 90032 | M11: West | N11: OFF-AP-10002892 | O11: Office Supplies | P11: Appliances | Q11: Belkin F5C206VTEL 6 Outlet Surge | R11: 114.9 | S11: 5 | T11: 0 | U11: 34.47
A12: 11 | B12: CA-2014-115812 | C12: 41799 | D12: 41804 | E12: Standard Class | F12: BH-11710 | G12: Brosina Hoffman | H12: Consumer | I12: United States | J12: Los Angeles | K12: California | L12: 90032 | M12: West | N12: FUR-TA-10001539 | O12: Furniture | P12: Tables | Q12: Chromcraft Rectangular Conference Tables | R12: 1706.184 | S12: 9 | T12: 0.2 | U12: 85.3092
A13: 12 | B13: CA-2014-115812 | C13: 41799 | D13: 41804 | E13: Standard Class | F13: BH-11710 | G13: Brosina Hoffman | H13: Consumer | I13: United States | J13: Los Angeles | K13: California | L13: 90032 | M13: West | N13: TEC-PH-10002033 | O13: Technology | P13: Phones | Q13: Konftel 250 Conference phone - Charcoal black | R13: 911.424 | S13: 4 | T13: 0.2 | U13: 68.3568
... A1001: 1000 | B1001: CA-2015-162537 | C1001: 42305 | D1001: 42311 | E1001: Standard Class | F1001: RD-19585 | G1001: Rob Dowd | H1001: Consumer | I1001: United States | J1001: Henderson | K1001: Kentucky | L1001: 42420 | M1001: South | N1001: FUR-FU-10001918 | O1001: Furniture | P1001: Furnishings | Q1001: C-Line Cubicle Keepers Polyproplyene Holder With Velcro Backings | R1001: 33.11 | S1001: 7 | T1001: 0 | U1001: 12.9129

Sheet Enriched Data
A1: Row ID | B1: Order ID | C1: Order Date | D1: Ship Date | E1: Ship Mode | F1: Customer ID | G1: Customer Name | H1: Segment | I1: Country | J1: City | K1: State | L1: Postal Code | M1: Region | N1: Product ID | O1: Category | P1: Sub-Category | Q1: Product Name | R1: Sales | S1: Quantity | T1: Discount | U1: Profit | V1: Order Year | W1: Order Month | X1: Order Quarter | Y1: Order Weekday | Z1: Shipping Delay (Days) | AA1: Unit Price | AB1: Profit Margin % | AC1: Discount Tier | AD1: Revenue Band | AE1: Order Size Category | AF1: Profitability Status | AG1: Performance Level | AH1: Customer Type | AI1: Delivery Speed Category
A2: 1 | B2: CA-2016-152156 | C2: 42682 | D2: 42685 | E2: Second Class | F2: CG-12520 | G2: Claire Gute | H2: Consumer | I2: United States | J2: Henderson | K2: Kentucky | L2: 42420 | M2: South | N2: FUR-BO-10001798 | O2: Furniture | P2: Bookcases | Q2: Bush Somerset Collection Bookcase | R2: 261.96 | S2: 2 | T2: 0 | U2: 41.9136 | V2: =YEAR(C2) -> 2016 | W2: =TEXT(C2,"mmm") -> Nov | X2: ="Q"&ROUNDUP(MONTH(C2)/3,0) -> Q4 | Y2: =TEXT(C2,"ddd") -> Tue | Z2: =D2-C2 -> 3 | AA2: =IFERROR(R2/S2,0) -> 130.98 | AB2: =IFERROR(U2/R2,0) -> 0.16 | AC2: =IF(T2=0,"No Discount",IF(T2<=0.2,"Low (1-20%)",IF(T2<=0.4,"Medium (21-40%)","High (40%+)"))) -> No Discount | AD2: =IF(R2<50,"Low (<$50)",IF(R2<200,"Medium ($50-$200)",IF(R2<500,"High ($200-$500)","Premium ($500+)"))) -> High ($200-$500) | AE2: =IF(S2<=2,"Small (1-2 units)",IF(S2<=5,"Medium (3-5 units)","Large (6+ units)")) -> Small (1-2 units) | AF2: =IF(U2<0,"Loss-Making","Profitable") -> Profitable | AG2: =IF(AB2<0,"Underperforming",IF(AB2<0.1,"Low Margin",IF(AB2<0.25,"Healthy Margin","High Margin"))) -> Healthy Margin | AH2: =IF(COUNTIF($F$2:$F$1001,F2)>1,"Repeat Customer","Single Purchase") -> Repeat Customer | AI2: =IF(Z2<=2,"Fast (<=2 days)",IF(Z2<=5,"Standard (3-5 days)","Slow (6+ days)")) -> Standard (3-5 days)
A3: 2 | B3: CA-2016-152156 | C3: 42682 | D3: 42685 | E3: Second Class | F3: CG-12520 | G3: Claire Gute | H3: Consumer | I3: United States | J3: Henderson | K3: Kentucky | L3: 42420 | M3: South | N3: FUR-CH-10000454 | O3: Furniture | P3: Chairs | Q3: Hon Deluxe Fabric Upholstered Stacking Chairs, Rounded Back | R3: 731.94 | S3: 3 | T3: 0 | U3: 219.582 | V3: =YEAR(C3) -> 2016 | W3: =TEXT(C3,"mmm") -> Nov | X3: ="Q"&ROUNDUP(MONTH(C3)/3,0) -> Q4 | Y3: =TEXT(C3,"ddd") -> Tue | Z3: =D3-C3 -> 3 | AA3: =IFERROR(R3/S3,0) -> 243.98 | AB3: =IFERROR(U3/R3,0) -> 0.3 | AC3: =IF(T3=0,"No Discount",IF(T3<=0.2,"Low (1-20%)",IF(T3<=0.4,"Medium (21-40%)","High (40%+)"))) -> No Discount | AD3: =IF(R3<50,"Low (<$50)",IF(R3<200,"Medium ($50-$200)",IF(R3<500,"High ($200-$500)","Premium ($500+)"))) -> Premium ($500+) | AE3: =IF(S3<=2,"Small (1-2 units)",IF(S3<=5,"Medium (3-5 units)","Large (6+ units)")) -> Medium (3-5 units) | AF3: =IF(U3<0,"Loss-Making","Profitable") -> Profitable | AG3: =IF(AB3<0,"Underperforming",IF(AB3<0.1,"Low Margin",IF(AB3<0.25,"Healthy Margin","High Margin"))) -> High Margin | AH3: =IF(COUNTIF($F$2:$F$1001,F3)>1,"Repeat Customer","Single Purchase") -> Repeat Customer | AI3: =IF(Z3<=2,"Fast (<=2 days)",IF(Z3<=5,"Standard (3-5 days)","Slow (6+ days)")) -> Standard (3-5 days)
A4: 3 | B4: CA-2016-138688 | C4: 42533 | D4: 42537 | E4: Second Class | F4: DV-13045 | G4: Darrin Van Huff | H4: Corporate | I4: United States | J4: Los Angeles | K4: California | L4: 90036 | M4: West | N4: OFF-LA-10000240 | O4: Office Supplies | P4: Labels | Q4: Self-Adhesive Address Labels for Typewriters by Universal | R4: 14.62 | S4: 2 | T4: 0 | U4: 6.8714 | V4: =YEAR(C4) -> 2016 | W4: =TEXT(C4,"mmm") -> Jun | X4: ="Q"&ROUNDUP(MONTH(C4)/3,0) -> Q2 | Y4: =TEXT(C4,"ddd") -> Sun | Z4: =D4-C4 -> 4 | AA4: =IFERROR(R4/S4,0) -> 7.31 | AB4: =IFERROR(U4/R4,0) -> 0.47 | AC4: =IF(T4=0,"No Discount",IF(T4<=0.2,"Low (1-20%)",IF(T4<=0.4,"Medium (21-40%)","High (40%+)"))) -> No Discount | AD4: =IF(R4<50,"Low (<$50)",IF(R4<200,"Medium ($50-$200)",IF(R4<500,"High ($200-$500)","Premium ($500+)"))) -> Low (<$50) | AE4: =IF(S4<=2,"Small (1-2 units)",IF(S4<=5,"Medium (3-5 units)","Large (6+ units)")) -> Small (1-2 units) | AF4: =IF(U4<0,"Loss-Making","Profitable") -> Profitable | AG4: =IF(AB4<0,"Underperforming",IF(AB4<0.1,"Low Margin",IF(AB4<0.25,"Healthy Margin","High Margin"))) -> High Margin | AH4: =IF(COUNTIF($F$2:$F$1001,F4)>1,"Repeat Customer","Single Purchase") -> Single Purchase | AI4: =IF(Z4<=2,"Fast (<=2 days)",IF(Z4<=5,"Standard (3-5 days)","Slow (6+ days)")) -> Standard (3-5 days)
A5: 4 | B5: US-2015-108966 | C5: 42288 | D5: 42295 | E5: Standard Class | F5: SO-20335 | G5: Sean O'Donnell | H5: Consumer | I5: United States | J5: Fort Lauderdale | K5: Florida | L5: 33311 | M5: South | N5: FUR-TA-10000577 | O5: Furniture | P5: Tables | Q5: Bretford CR4500 Series Slim Rectangular Table | R5: 957.5775 | S5: 5 | T5: 0.45 | U5: -383.031 | V5: =YEAR(C5) -> 2015 | W5: =TEXT(C5,"mmm") -> Oct | X5: ="Q"&ROUNDUP(MONTH(C5)/3,0) -> Q4 | Y5: =TEXT(C5,"ddd") -> Sun | Z5: =D5-C5 -> 7 | AA5: =IFERROR(R5/S5,0) -> 191.5155 | AB5: =IFERROR(U5/R5,0) -> -0.4 | AC5: =IF(T5=0,"No Discount",IF(T5<=0.2,"Low (1-20%)",IF(T5<=0.4,"Medium (21-40%)","High (40%+)"))) -> High (40%+) | AD5: =IF(R5<50,"Low (<$50)",IF(R5<200,"Medium ($50-$200)",IF(R5<500,"High ($200-$500)","Premium ($500+)"))) -> Premium ($500+) | AE5: =IF(S5<=2,"Small (1-2 units)",IF(S5<=5,"Medium (3-5 units)","Large (6+ units)")) -> Medium (3-5 units) | AF5: =IF(U5<0,"Loss-Making","Profitable") -> Loss-Making | AG5: =IF(AB5<0,"Underperforming",IF(AB5<0.1,"Low Margin",IF(AB5<0.25,"Healthy Margin","High Margin"))) -> Underperforming | AH5: =IF(COUNTIF($F$2:$F$1001,F5)>1,"Repeat Customer","Single Purchase") -> Repeat Customer | AI5: =IF(Z5<=2,"Fast (<=2 days)",IF(Z5<=5,"Standard (3-5 days)","Slow (6+ days)")) -> Slow (6+ days)
A6: 5 | B6: US-2015-108966 | C6: 42288 | D6: 42295 | E6: Standard Class | F6: SO-20335 | G6: Sean O'Donnell | H6: Consumer | I6: United States | J6: Fort Lauderdale | K6: Florida | L6: 33311 | M6: South | N6: OFF-ST-10000760 | O6: Office Supplies | P6: Storage | Q6: Eldon Fold 'N Roll Cart System | R6: 22.368 | S6: 2 | T6: 0.2 | U6: 2.5164 | V6: =YEAR(C6) -> 2015 | W6: =TEXT(C6,"mmm") -> Oct | X6: ="Q"&ROUNDUP(MONTH(C6)/3,0) -> Q4 | Y6: =TEXT(C6,"ddd") -> Sun | Z6: =D6-C6 -> 7 | AA6: =IFERROR(R6/S6,0) -> 11.184 | AB6: =IFERROR(U6/R6,0) -> 0.1125 | AC6: =IF(T6=0,"No Discount",IF(T6<=0.2,"Low (1-20%)",IF(T6<=0.4,"Medium (21-40%)","High (40%+)"))) -> Low (1-20%) | AD6: =IF(R6<50,"Low (<$50)",IF(R6<200,"Medium ($50-$200)",IF(R6<500,"High ($200-$500)","Premium ($500+)"))) -> Low (<$50) | AE6: =IF(S6<=2,"Small (1-2 units)",IF(S6<=5,"Medium (3-5 units)","Large (6+ units)")) -> Small (1-2 units) | AF6: =IF(U6<0,"Loss-Making","Profitable") -> Profitable | AG6: =IF(AB6<0,"Underperforming",IF(AB6<0.1,"Low Margin",IF(AB6<0.25,"Healthy Margin","High Margin"))) -> Healthy Margin | AH6: =IF(COUNTIF($F$2:$F$1001,F6)>1,"Repeat Customer","Single Purchase") -> Repeat Customer | AI6: =IF(Z6<=2,"Fast (<=2 days)",IF(Z6<=5,"Standard (3-5 days)","Slow (6+ days)")) -> Slow (6+ days)
A7: 6 | B7: CA-2014-115812 | C7: 41799 | D7: 41804 | E7: Standard Class | F7: BH-11710 | G7: Brosina Hoffman | H7: Consumer | I7: United States | J7: Los Angeles | K7: California | L7: 90032 | M7: West | N7: FUR-FU-10001487 | O7: Furniture | P7: Furnishings | Q7: Eldon Expressions Wood and Plastic Desk Accessories, Cherry Wood | R7: 48.86 | S7: 7 | T7: 0 | U7: 14.1694 | V7: =YEAR(C7) -> 2014 | W7: =TEXT(C7,"mmm") -> Jun | X7: ="Q"&ROUNDUP(MONTH(C7)/3,0) -> Q2 | Y7: =TEXT(C7,"ddd") -> Mon | Z7: =D7-C7 -> 5 | AA7: =IFERROR(R7/S7,0) -> 6.98 | AB7: =IFERROR(U7/R7,0) -> 0.29 | AC7: =IF(T7=0,"No Discount",IF(T7<=0.2,"Low (1-20%)",IF(T7<=0.4,"Medium (21-40%)","High (40%+)"))) -> No Discount | AD7: =IF(R7<50,"Low (<$50)",IF(R7<200,"Medium ($50-$200)",IF(R7<500,"High ($200-$500)","Premium ($500+)"))) -> Low (<$50) | AE7: =IF(S7<=2,"Small (1-2 units)",IF(S7<=5,"Medium (3-5 units)","Large (6+ units)")) -> Large (6+ units) | AF7: =IF(U7<0,"Loss-Making","Profitable") -> Profitable | AG7: =IF(AB7<0,"Underperforming",IF(AB7<0.1,"Low Margin",IF(AB7<0.25,"Healthy Margin","High Margin"))) -> High Margin | AH7: =IF(COUNTIF($F$2:$F$1001,F7)>1,"Repeat Customer","Single Purchase") -> Repeat Customer | AI7: =IF(Z7<=2,"Fast (<=2 days)",IF(Z7<=5,"Standard (3-5 days)","Slow (6+ days)")) -> Standard (3-5 days)
A8: 7 | B8: CA-2014-115812 | C8: 41799 | D8: 41804 | E8: Standard Class | F8: BH-11710 | G8: Brosina Hoffman | H8: Consumer | I8: United States | J8: Los Angeles | K8: California | L8: 90032 | M8: West | N8: OFF-AR-10002833 | O8: Office Supplies | P8: Art | Q8: Newell 322 | R8: 7.28 | S8: 4 | T8: 0 | U8: 1.9656 | V8: =YEAR(C8) -> 2014 | W8: =TEXT(C8,"mmm") -> Jun | X8: ="Q"&ROUNDUP(MONTH(C8)/3,0) -> Q2 | Y8: =TEXT(C8,"ddd") -> Mon | Z8: =D8-C8 -> 5 | AA8: =IFERROR(R8/S8,0) -> 1.82 | AB8: =IFERROR(U8/R8,0) -> 0.27 | AC8: =IF(T8=0,"No Discount",IF(T8<=0.2,"Low (1-20%)",IF(T8<=0.4,"Medium (21-40%)","High (40%+)"))) -> No Discount | AD8: =IF(R8<50,"Low (<$50)",IF(R8<200,"Medium ($50-$200)",IF(R8<500,"High ($200-$500)","Premium ($500+)"))) -> Low (<$50) | AE8: =IF(S8<=2,"Small (1-2 units)",IF(S8<=5,"Medium (3-5 units)","Large (6+ units)")) -> Medium (3-5 units) | AF8: =IF(U8<0,"Loss-Making","Profitable") -> Profitable | AG8: =IF(AB8<0,"Underperforming",IF(AB8<0.1,"Low Margin",IF(AB8<0.25,"Healthy Margin","High Margin"))) -> High Margin | AH8: =IF(COUNTIF($F$2:$F$1001,F8)>1,"Repeat Customer","Single Purchase") -> Repeat Customer | AI8: =IF(Z8<=2,"Fast (<=2 days)",IF(Z8<=5,"Standard (3-5 days)","Slow (6+ days)")) -> Standard (3-5 days)
A9: 8 | B9: CA-2014-115812 | C9: 41799 | D9: 41804 | E9: Standard Class | F9: BH-11710 | G9: Brosina Hoffman | H9: Consumer | I9: United States | J9: Los Angeles | K9: California | L9: 90032 | M9: West | N9: TEC-PH-10002275 | O9: Technology | P9: Phones | Q9: Mitel 5320 IP Phone VoIP phone | R9: 907.152 | S9: 6 | T9: 0.2 | U9: 90.7152 | V9: =YEAR(C9) -> 2014 | W9: =TEXT(C9,"mmm") -> Jun | X9: ="Q"&ROUNDUP(MONTH(C9)/3,0) -> Q2 | Y9: =TEXT(C9,"ddd") -> Mon | Z9: =D9-C9 -> 5 | AA9: =IFERROR(R9/S9,0) -> 151.192 | AB9: =IFERROR(U9/R9,0) -> 0.1 | AC9: =IF(T9=0,"No Discount",IF(T9<=0.2,"Low (1-20%)",IF(T9<=0.4,"Medium (21-40%)","High (40%+)"))) -> Low (1-20%) | AD9: =IF(R9<50,"Low (<$50)",IF(R9<200,"Medium ($50-$200)",IF(R9<500,"High ($200-$500)","Premium ($500+)"))) -> Premium ($500+) | AE9: =IF(S9<=2,"Small (1-2 units)",IF(S9<=5,"Medium (3-5 units)","Large (6+ units)")) -> Large (6+ units) | AF9: =IF(U9<0,"Loss-Making","Profitable") -> Profitable | AG9: =IF(AB9<0,"Underperforming",IF(AB9<0.1,"Low Margin",IF(AB9<0.25,"Healthy Margin","High Margin"))) -> Healthy Margin | AH9: =IF(COUNTIF($F$2:$F$1001,F9)>1,"Repeat Customer","Single Purchase") -> Repeat Customer | AI9: =IF(Z9<=2,"Fast (<=2 days)",IF(Z9<=5,"Standard (3-5 days)","Slow (6+ days)")) -> Standard (3-5 days)
A10: 9 | B10: CA-2014-115812 | C10: 41799 | D10: 41804 | E10: Standard Class | F10: BH-11710 | G10: Brosina Hoffman | H10: Consumer | I10: United States | J10: Los Angeles | K10: California | L10: 90032 | M10: West | N10: OFF-BI-10003910 | O10: Office Supplies | P10: Binders | Q10: DXL Angle-View Binders with Locking Rings by Samsill | R10: 18.504 | S10: 3 | T10: 0.2 | U10: 5.7825 | V10: =YEAR(C10) -> 2014 | W10: =TEXT(C10,"mmm") -> Jun | X10: ="Q"&ROUNDUP(MONTH(C10)/3,0) -> Q2 | Y10: =TEXT(C10,"ddd") -> Mon | Z10: =D10-C10 -> 5 | AA10: =IFERROR(R10/S10,0) -> 6.168 | AB10: =IFERROR(U10/R10,0) -> 0.3125 | AC10: =IF(T10=0,"No Discount",IF(T10<=0.2,"Low (1-20%)",IF(T10<=0.4,"Medium (21-40%)","High (40%+)"))) -> Low (1-20%) | AD10: =IF(R10<50,"Low (<$50)",IF(R10<200,"Medium ($50-$200)",IF(R10<500,"High ($200-$500)","Premium ($500+)"))) -> Low (<$50) | AE10: =IF(S10<=2,"Small (1-2 units)",IF(S10<=5,"Medium (3-5 units)","Large (6+ units)")) -> Medium (3-5 units) | AF10: =IF(U10<0,"Loss-Making","Profitable") -> Profitable | AG10: =IF(AB10<0,"Underperforming",IF(AB10<0.1,"Low Margin",IF(AB10<0.25,"Healthy Margin","High Margin"))) -> High Margin | AH10: =IF(COUNTIF($F$2:$F$1001,F10)>1,"Repeat Customer","Single Purchase") -> Repeat Customer | AI10: =IF(Z10<=2,"Fast (<=2 days)",IF(Z10<=5,"Standard (3-5 days)","Slow (6+ days)")) -> Standard (3-5 days)
A11: 10 | B11: CA-2014-115812 | C11: 41799 | D11: 41804 | E11: Standard Class | F11: BH-11710 | G11: Brosina Hoffman | H11: Consumer | I11: United States | J11: Los Angeles | K11: California | L11: 90032 | M11: West | N11: OFF-AP-10002892 | O11: Office Supplies | P11: Appliances | Q11: Belkin F5C206VTEL 6 Outlet Surge | R11: 114.9 | S11: 5 | T11: 0 | U11: 34.47 | V11: =YEAR(C11) -> 2014 | W11: =TEXT(C11,"mmm") -> Jun | X11: ="Q"&ROUNDUP(MONTH(C11)/3,0) -> Q2 | Y11: =TEXT(C11,"ddd") -> Mon | Z11: =D11-C11 -> 5 | AA11: =IFERROR(R11/S11,0) -> 22.98 | AB11: =IFERROR(U11/R11,0) -> 0.3 | AC11: =IF(T11=0,"No Discount",IF(T11<=0.2,"Low (1-20%)",IF(T11<=0.4,"Medium (21-40%)","High (40%+)"))) -> No Discount | AD11: =IF(R11<50,"Low (<$50)",IF(R11<200,"Medium ($50-$200)",IF(R11<500,"High ($200-$500)","Premium ($500+)"))) -> Medium ($50-$200) | AE11: =IF(S11<=2,"Small (1-2 units)",IF(S11<=5,"Medium (3-5 units)","Large (6+ units)")) -> Medium (3-5 units) | AF11: =IF(U11<0,"Loss-Making","Profitable") -> Profitable | AG11: =IF(AB11<0,"Underperforming",IF(AB11<0.1,"Low Margin",IF(AB11<0.25,"Healthy Margin","High Margin"))) -> High Margin | AH11: =IF(COUNTIF($F$2:$F$1001,F11)>1,"Repeat Customer","Single Purchase") -> Repeat Customer | AI11: =IF(Z11<=2,"Fast (<=2 days)",IF(Z11<=5,"Standard (3-5 days)","Slow (6+ days)")) -> Standard (3-5 days)
A12: 11 | B12: CA-2014-115812 | C12: 41799 | D12: 41804 | E12: Standard Class | F12: BH-11710 | G12: Brosina Hoffman | H12: Consumer | I12: United States | J12: Los Angeles | K12: California | L12: 90032 | M12: West | N12: FUR-TA-10001539 | O12: Furniture | P12: Tables | Q12: Chromcraft Rectangular Conference Tables | R12: 1706.184 | S12: 9 | T12: 0.2 | U12: 85.3092 | V12: =YEAR(C12) -> 2014 | W12: =TEXT(C12,"mmm") -> Jun | X12: ="Q"&ROUNDUP(MONTH(C12)/3,0) -> Q2 | Y12: =TEXT(C12,"ddd") -> Mon | Z12: =D12-C12 -> 5 | AA12: =IFERROR(R12/S12,0) -> 189.576 | AB12: =IFERROR(U12/R12,0) -> 0.05 | AC12: =IF(T12=0,"No Discount",IF(T12<=0.2,"Low (1-20%)",IF(T12<=0.4,"Medium (21-40%)","High (40%+)"))) -> Low (1-20%) | AD12: =IF(R12<50,"Low (<$50)",IF(R12<200,"Medium ($50-$200)",IF(R12<500,"High ($200-$500)","Premium ($500+)"))) -> Premium ($500+) | AE12: =IF(S12<=2,"Small (1-2 units)",IF(S12<=5,"Medium (3-5 units)","Large (6+ units)")) -> Large (6+ units) | AF12: =IF(U12<0,"Loss-Making","Profitable") -> Profitable | AG12: =IF(AB12<0,"Underperforming",IF(AB12<0.1,"Low Margin",IF(AB12<0.25,"Healthy Margin","High Margin"))) -> Low Margin | AH12: =IF(COUNTIF($F$2:$F$1001,F12)>1,"Repeat Customer","Single Purchase") -> Repeat Customer | AI12: =IF(Z12<=2,"Fast (<=2 days)",IF(Z12<=5,"Standard (3-5 days)","Slow (6+ days)")) -> Standard (3-5 days)
A13: 12 | B13: CA-2014-115812 | C13: 41799 | D13: 41804 | E13: Standard Class | F13: BH-11710 | G13: Brosina Hoffman | H13: Consumer | I13: United States | J13: Los Angeles | K13: California | L13: 90032 | M13: West | N13: TEC-PH-10002033 | O13: Technology | P13: Phones | Q13: Konftel 250 Conference phone - Charcoal black | R13: 911.424 | S13: 4 | T13: 0.2 | U13: 68.3568 | V13: =YEAR(C13) -> 2014 | W13: =TEXT(C13,"mmm") -> Jun | X13: ="Q"&ROUNDUP(MONTH(C13)/3,0) -> Q2 | Y13: =TEXT(C13,"ddd") -> Mon | Z13: =D13-C13 -> 5 | AA13: =IFERROR(R13/S13,0) -> 227.856 | AB13: =IFERROR(U13/R13,0) -> 0.075 | AC13: =IF(T13=0,"No Discount",IF(T13<=0.2,"Low (1-20%)",IF(T13<=0.4,"Medium (21-40%)","High (40%+)"))) -> Low (1-20%) | AD13: =IF(R13<50,"Low (<$50)",IF(R13<200,"Medium ($50-$200)",IF(R13<500,"High ($200-$500)","Premium ($500+)"))) -> Premium ($500+) | AE13: =IF(S13<=2,"Small (1-2 units)",IF(S13<=5,"Medium (3-5 units)","Large (6+ units)")) -> Medium (3-5 units) | AF13: =IF(U13<0,"Loss-Making","Profitable") -> Profitable | AG13: =IF(AB13<0,"Underperforming",IF(AB13<0.1,"Low Margin",IF(AB13<0.25,"Healthy Margin","High Margin"))) -> Low Margin | AH13: =IF(COUNTIF($F$2:$F$1001,F13)>1,"Repeat Customer","Single Purchase") -> Repeat Customer | AI13: =IF(Z13<=2,"Fast (<=2 days)",IF(Z13<=5,"Standard (3-5 days)","Slow (6+ days)")) -> Standard (3-5 days)
... A1001: 1000 | B1001: CA-2015-162537 | C1001: 42305 | D1001: 42311 | E1001: Standard Class | F1001: RD-19585 | G1001: Rob Dowd | H1001: Consumer | I1001: United States | J1001: Henderson | K1001: Kentucky | L1001: 42420 | M1001: South | N1001: FUR-FU-10001918 | O1001: Furniture | P1001: Furnishings | Q1001: C-Line Cubicle Keepers Polyproplyene Holder With Velcro Backings | R1001: 33.11 | S1001: 7 | T1001: 0 | U1001: 12.9129 | V1001: =YEAR(C1001) -> 2015 | W1001: =TEXT(C1001,"mmm") -> Oct | X1001: ="Q"&ROUNDUP(MONTH(C1001)/3,0) -> Q4 | Y1001: =TEXT(C1001,"ddd") -> Wed | Z1001: =D1001-C1001 -> 6 | AA1001: =IFERROR(R1001/S1001,0) -> 4.73 | AB1001: =IFERROR(U1001/R1001,0) -> 0.39 | AC1001: =IF(T1001=0,"No Discount",IF(T1001<=0.2,"Low (1-20%)",IF(T1001<=0.4,"Medium (21-40%)","High (40%+)"))) -> No Discount | AD1001: =IF(R1001<50,"Low (<$50)",IF(R1001<200,"Medium ($50-$200)",IF(R1001<500,"High ($200-$500)","Premium ($500+)"))) -> Low (<$50) | AE1001: =IF(S1001<=2,"Small (1-2 units)",IF(S1001<=5,"Medium (3-5 units)","Large (6+ units)")) -> Large (6+ units) | AF1001: =IF(U1001<0,"Loss-Making","Profitable") -> Profitable | AG1001: =IF(AB1001<0,"Underperforming",IF(AB1001<0.1,"Low Margin",IF(AB1001<0.25,"Healthy Margin","High Margin"))) -> High Margin | AH1001: =IF(COUNTIF($F$2:$F$1001,F1001)>1,"Repeat Customer","Single Purchase") -> Repeat Customer | AI1001: =IF(Z1001<=2,"Fast (<=2 days)",IF(Z1001<=5,"Standard (3-5 days)","Slow (6+ days)")) -> Slow (6+ days)

Sheet Summary Tables
A1: PIVOT-STYLE SUMMARY TABLES
A2: Built entirely with SUMIFS / COUNTIFS / AVERAGEIFS against the Enriched Data table (live, recalculates automatically).
A4: 1. Performance by Category
A5: Category | B5: Total Sales | C5: Total Profit | D5: Profit Margin % | E5: Order Lines
A6: Furniture | B6: =SUMIF('Enriched Data'!$O$2:$O$1001,A6,'Enriched Data'!$R$2:$R$1001) -> 79377.579 | C6: =SUMIF('Enriched Data'!$O$2:$O$1001,A6,'Enriched Data'!$U$2:$U$1001) -> -1742.0193 | D6: =IFERROR(C6/B6,0) -> -0.021945987 | E6: =COUNTIF('Enriched Data'!$O$2:$O$1001,A6) -> 207
A7: Office Supplies | B7: =SUMIF('Enriched Data'!$O$2:$O$1001,A7,'Enriched Data'!$R$2:$R$1001) -> 68253.347 | C7: =SUMIF('Enriched Data'!$O$2:$O$1001,A7,'Enriched Data'!$U$2:$U$1001) -> 12470.729 | D7: =IFERROR(C7/B7,0) -> 0.18271234 | E7: =COUNTIF('Enriched Data'!$O$2:$O$1001,A7) -> 603
A8: Technology | B8: =SUMIF('Enriched Data'!$O$2:$O$1001,A8,'Enriched Data'!$R$2:$R$1001) -> 93499.842 | C8: =SUMIF('Enriched Data'!$O$2:$O$1001,A8,'Enriched Data'!$U$2:$U$1001) -> 8017.4697 | D8: =IFERROR(C8/B8,0) -> 0.085748484 | E8: =COUNTIF('Enriched Data'!$O$2:$O$1001,A8) -> 190
A10: 2. Performance by Sub-Category
A11: Sub-Category | B11: Total Sales | C11: Total Profit | D11: Profit Margin % | E11: Order Lines
A12: Accessories | B12: =SUMIF('Enriched Data'!$P$2:$P$1001,A12,'Enriched Data'!$R$2:$R$1001) -> 20481.394 | C12: =SUMIF('Enriched Data'!$P$2:$P$1001,A12,'Enriched Data'!$U$2:$U$1001) -> 5300.3493 | D12: =IFERROR(C12/B12,0) -> 0.2587885 | E12: =COUNTIF('Enriched Data'!$P$2:$P$1001,A12) -> 83
A13: Appliances | B13: =SUMIF('Enriched Data'!$P$2:$P$1001,A13,'Enriched Data'!$R$2:$R$1001) -> 8369.878 | C13: =SUMIF('Enriched Data'!$P$2:$P$1001,A13,'Enriched Data'!$U$2:$U$1001) -> 868.67 | D13: =IFERROR(C13/B13,0) -> 0.10378526 | E13: =COUNTIF('Enriched Data'!$P$2:$P$1001,A13) -> 43
A14: Art | B14: =SUMIF('Enriched Data'!$P$2:$P$1001,A14,'Enriched Data'!$R$2:$R$1001) -> 3858.084 | C14: =SUMIF('Enriched Data'!$P$2:$P$1001,A14,'Enriched Data'!$U$2:$U$1001) -> 754.868 | D14: =IFERROR(C14/B14,0) -> 0.19565878 | E14: =COUNTIF('Enriched Data'!$P$2:$P$1001,A14) -> 81
A15: Binders | B15: =SUMIF('Enriched Data'!$P$2:$P$1001,A15,'Enriched Data'!$R$2:$R$1001) -> 21412.529 | C15: =SUMIF('Enriched Data'!$P$2:$P$1001,A15,'Enriched Data'!$U$2:$U$1001) -> 4913.6912 | D15: =IFERROR(C15/B15,0) -> 0.22947739 | E15: =COUNTIF('Enriched Data'!$P$2:$P$1001,A15) -> 145
A16: Bookcases | B16: =SUMIF('Enriched Data'!$P$2:$P$1001,A16,'Enriched Data'!$R$2:$R$1001) -> 13834.99 | C16: =SUMIF('Enriched Data'!$P$2:$P$1001,A16,'Enriched Data'!$U$2:$U$1001) -> -1971.6986 | D16: =IFERROR(C16/B16,0) -> -0.14251536 | E16: =COUNTIF('Enriched Data'!$P$2:$P$1001,A16) -> 21
A17: Chairs | B17: =SUMIF('Enriched Data'!$P$2:$P$1001,A17,'Enriched Data'!$R$2:$R$1001) -> 30809.088 | C17: =SUMIF('Enriched Data'!$P$2:$P$1001,A17,'Enriched Data'!$U$2:$U$1001) -> 2905.0913 | D17: =IFERROR(C17/B17,0) -> 0.094293323 | E17: =COUNTIF('Enriched Data'!$P$2:$P$1001,A17) -> 58
A18: Copiers | B18: =SUMIF('Enriched Data'!$P$2:$P$1001,A18,'Enriched Data'!$R$2:$R$1001) -> 9359.832 | C18: =SUMIF('Enriched Data'!$P$2:$P$1001,A18,'Enriched Data'!$U$2:$U$1001) -> 3662.9348 | D18: =IFERROR(C18/B18,0) -> 0.39134621 | E18: =COUNTIF('Enriched Data'!$P$2:$P$1001,A18) -> 6
A19: Envelopes | B19: =SUMIF('Enriched Data'!$P$2:$P$1001,A19,'Enriched Data'!$R$2:$R$1001) -> 2109.332 | C19: =SUMIF('Enriched Data'!$P$2:$P$1001,A19,'Enriched Data'!$U$2:$U$1001) -> 827.1686 | D19: =IFERROR(C19/B19,0) -> 0.39214718 | E19: =COUNTIF('Enriched Data'!$P$2:$P$1001,A19) -> 30
A20: Fasteners | B20: =SUMIF('Enriched Data'!$P$2:$P$1001,A20,'Enriched Data'!$R$2:$R$1001) -> 381.66 | C20: =SUMIF('Enriched Data'!$P$2:$P$1001,A20,'Enriched Data'!$U$2:$U$1001) -> 139.8693 | D20: =IFERROR(C20/B20,0) -> 0.36647618 | E20: =COUNTIF('Enriched Data'!$P$2:$P$1001,A20) -> 21
A21: Furnishings | B21: =SUMIF('Enriched Data'!$P$2:$P$1001,A21,'Enriched Data'!$R$2:$R$1001) -> 10256.894 | C21: =SUMIF('Enriched Data'!$P$2:$P$1001,A21,'Enriched Data'!$U$2:$U$1001) -> 776.5627 | D21: =IFERROR(C21/B21,0) -> 0.075711292 | E21: =COUNTIF('Enriched Data'!$P$2:$P$1001,A21) -> 95
A22: Labels | B22: =SUMIF('Enriched Data'!$P$2:$P$1001,A22,'Enriched Data'!$R$2:$R$1001) -> 1534.34 | C22: =SUMIF('Enriched Data'!$P$2:$P$1001,A22,'Enriched Data'!$U$2:$U$1001) -> 652.5635 | D22: =IFERROR(C22/B22,0) -> 0.42530567 | E22: =COUNTIF('Enriched Data'!$P$2:$P$1001,A22) -> 41
A23: Machines | B23: =SUMIF('Enriched Data'!$P$2:$P$1001,A23,'Enriched Data'!$R$2:$R$1001) -> 32622.116 | C23: =SUMIF('Enriched Data'!$P$2:$P$1001,A23,'Enriched Data'!$U$2:$U$1001) -> -4951.3543 | D23: =IFERROR(C23/B23,0) -> -0.15177907 | E23: =COUNTIF('Enriched Data'!$P$2:$P$1001,A23) -> 13
... A28: Tables | B28: =SUMIF('Enriched Data'!$P$2:$P$1001,A28,'Enriched Data'!$R$2:$R$1001) -> 24476.606 | C28: =SUMIF('Enriched Data'!$P$2:$P$1001,A28,'Enriched Data'!$U$2:$U$1001) -> -3451.9747 | D28: =IFERROR(C28/B28,0) -> -0.14103159 | E28: =COUNTIF('Enriched Data'!$P$2:$P$1001,A28) -> 33
A30: 3. Performance by Region
A31: Region | B31: Total Sales | C31: Total Profit | D31: Profit Margin % | E31: Avg Order Value
A32: Central | B32: =SUMIF('Enriched Data'!$M$2:$M$1001,A32,'Enriched Data'!$R$2:$R$1001) -> 67009.848 | C32: =SUMIF('Enriched Data'!$M$2:$M$1001,A32,'Enriched Data'!$U$2:$U$1001) -> 2169.6442 | D32: =IFERROR(C32/B32,0) -> 0.03237799 | E32: =IFERROR(B32/COUNTIF('Enriched Data'!$M$2:$M$1001,A32),0) -> 273.50959
A33: East | B33: =SUMIF('Enriched Data'!$M$2:$M$1001,A33,'Enriched Data'!$R$2:$R$1001) -> 59491.641 | C33: =SUMIF('Enriched Data'!$M$2:$M$1001,A33,'Enriched Data'!$U$2:$U$1001) -> 2790.3043 | D33: =IFERROR(C33/B33,0) -> 0.04690246 | E33: =IFERROR(B33/COUNTIF('Enriched Data'!$M$2:$M$1001,A33),0) -> 190.06914
A34: South | B34: =SUMIF('Enriched Data'!$M$2:$M$1001,A34,'Enriched Data'!$R$2:$R$1001) -> 43563.958 | C34: =SUMIF('Enriched Data'!$M$2:$M$1001,A34,'Enriched Data'!$U$2:$U$1001) -> 2860.7752 | D34: =IFERROR(C34/B34,0) -> 0.065668394 | E34: =IFERROR(B34/COUNTIF('Enriched Data'!$M$2:$M$1001,A34),0) -> 308.96424
A35: West | B35: =SUMIF('Enriched Data'!$M$2:$M$1001,A35,'Enriched Data'!$R$2:$R$1001) -> 71065.32 | C35: =SUMIF('Enriched Data'!$M$2:$M$1001,A35,'Enriched Data'!$U$2:$U$1001) -> 10925.455 | D35: =IFERROR(C35/B35,0) -> 0.15373822 | E35: =IFERROR(B35/COUNTIF('Enriched Data'!$M$2:$M$1001,A35),0) -> 236.09741
A37: 4. Performance by Customer Segment
A38: Segment | B38: Total Sales | C38: Total Profit | D38: Profit Margin % | E38: Order Lines
A39: Consumer | B39: =SUMIF('Enriched Data'!$H$2:$H$1001,A39,'Enriched Data'!$R$2:$R$1001) -> 118554.3 | C39: =SUMIF('Enriched Data'!$H$2:$H$1001,A39,'Enriched Data'!$U$2:$U$1001) -> 9367.7052 | D39: =IFERROR(C39/B39,0) -> 0.079016155 | E39: =COUNTIF('Enriched Data'!$H$2:$H$1001,A39) -> 547
A40: Corporate | B40: =SUMIF('Enriched Data'!$H$2:$H$1001,A40,'Enriched Data'!$R$2:$R$1001) -> 70821.302 | C40: =SUMIF('Enriched Data'!$H$2:$H$1001,A40,'Enriched Data'!$U$2:$U$1001) -> 1976.6129 | D40: =IFERROR(C40/B40,0) -> 0.027909864 | E40: =COUNTIF('Enriched Data'!$H$2:$H$1001,A40) -> 283
A41: Home Office | B41: =SUMIF('Enriched Data'!$H$2:$H$1001,A41,'Enriched Data'!$R$2:$R$1001) -> 51755.163 | C41: =SUMIF('Enriched Data'!$H$2:$H$1001,A41,'Enriched Data'!$U$2:$U$1001) -> 7401.8611 | D41: =IFERROR(C41/B41,0) -> 0.14301686 | E41: =COUNTIF('Enriched Data'!$H$2:$H$1001,A41) -> 170
A43: 5. Performance by Ship Mode
A44: Ship Mode | B44: Total Sales | C44: Total Profit | D44: Profit Margin % | E44: Order Lines
A45: First Class | B45: =SUMIF('Enriched Data'!$E$2:$E$1001,A45,'Enriched Data'!$R$2:$R$1001) -> 36982.738 | C45: =SUMIF('Enriched Data'!$E$2:$E$1001,A45,'Enriched Data'!$U$2:$U$1001) -> 4804.9781 | D45: =IFERROR(C45/B45,0) -> 0.12992489 | E45: =COUNTIF('Enriched Data'!$E$2:$E$1001,A45) -> 184
A46: Same Day | B46: =SUMIF('Enriched Data'!$E$2:$E$1001,A46,'Enriched Data'!$R$2:$R$1001) -> 13988.912 | C46: =SUMIF('Enriched Data'!$E$2:$E$1001,A46,'Enriched Data'!$U$2:$U$1001) -> -2832.7894 | D46: =IFERROR(C46/B46,0) -> -0.20250248 | E46: =COUNTIF('Enriched Data'!$E$2:$E$1001,A46) -> 17
A47: Second Class | B47: =SUMIF('Enriched Data'!$E$2:$E$1001,A47,'Enriched Data'!$R$2:$R$1001) -> 49014.086 | C47: =SUMIF('Enriched Data'!$E$2:$E$1001,A47,'Enriched Data'!$U$2:$U$1001) -> 4278.3373 | D47: =IFERROR(C47/B47,0) -> 0.087287914 | E47: =COUNTIF('Enriched Data'!$E$2:$E$1001,A47) -> 213
A48: Standard Class | B48: =SUMIF('Enriched Data'!$E$2:$E$1001,A48,'Enriched Data'!$R$2:$R$1001) -> 141145.03 | C48: =SUMIF('Enriched Data'!$E$2:$E$1001,A48,'Enriched Data'!$U$2:$U$1001) -> 12495.653 | D48: =IFERROR(C48/B48,0) -> 0.088530592 | E48: =COUNTIF('Enriched Data'!$E$2:$E$1001,A48) -> 586
A50: 6. Yearly Sales & Profit Trend
...

Sheet KPI Dashboard
B1: RETAIL SALES PERFORMANCE — EXECUTIVE KPI DASHBOARD
B2: US Superstore Retail Dataset | Period: 2014 - 2017 | All figures in USD
B4: TOTAL SALES | F4: TOTAL PROFIT | J4: OVERALL PROFIT MARGIN | N4: TOTAL ORDERS (DISTINCT)
B5: =SUM('Enriched Data'!$R$2:$R$1001) -> 241130.77 | F5: =SUM('Enriched Data'!$U$2:$U$1001) -> 18746.179 | J5: =F5/B5 -> 0.077742792 | N5: =SUMPRODUCT(1/COUNTIF('Enriched Data'!$B$2:$B$1001,'Enriched Data'!$B$2:$B$1001)) -> 479
B7: AVERAGE ORDER VALUE | F7: AVERAGE DISCOUNT RATE | J7: TOTAL UNIQUE CUSTOMERS | N7: LOSS-MAKING ORDER LINES %
B8: =B5/N5 -> 503.40453 | F8: =AVERAGE('Enriched Data'!$T$2:$T$1001) -> 0.16268 | J8: =SUMPRODUCT(1/COUNTIF('Enriched Data'!$F$2:$F$1001,'Enriched Data'!$F$2:$F$1001)) -> 362 | N8: =COUNTIF('Enriched Data'!$AF$2:$AF$1001,"Loss-Making")/1000 -> 0.186
B10: Note: KPI cards are 100% formula-driven from the Enriched Data table — they update automatically if the underlying data changes.

Sheet Business Questions
A1: BUSINESS QUESTIONS & ANSWERS
A2: 40 questions, beginner to advanced, answered with real figures. Source = Summary Tables / Enriched Data.
A4: # | B4: Level | C4: Business Question | D4: Answer | E4: Supporting Sheet / Method
A5: 1 | B5: Beginner | C5: What is the total revenue generated across all orders? | D5: Total Sales = $241,131 across 1,000 order lines (479 distinct orders), 2014-2017. | E5: KPI Dashboard - Total Sales card
A6: 2 | B6: Beginner | C6: What is the total profit generated? | D6: Total Profit = $18,746, an overall blended profit margin of 7.8% on sales. | E6: KPI Dashboard - Total Profit / Margin cards
A7: 3 | B7: Beginner | C7: Which product category generates the most sales? | D7: Technology leads with $93,500 (38.8% of total sales), ahead of Furniture ($79,378) and Office Supplies ($68,253). | E7: Summary Tables - Section 1
A8: 4 | B8: Beginner | C8: Which category is the most profitable? | D8: Office Supplies is most profitable in absolute terms ($12,471, 18.3% margin); Technology contributes $8,017 at 8.6% margin. | E8: Summary Tables - Section 1
A9: 5 | B9: Beginner | C9: Which category is losing money? | D9: Furniture is the only category with a negative overall margin (-2.2%), losing $1,742 despite $79,378 in sales. | E9: Summary Tables - Section 1
A10: 6 | B10: Beginner | C10: Which region generates the most sales? | D10: The West region leads with $71,065 in sales, followed by Central ($67,010), East ($59,492) and South ($43,564). | E10: Summary Tables - Section 3
A11: 7 | B11: Beginner | C11: Which region is the most profitable? | D11: West is both the top-selling and most profitable region (15.4% margin, $10,925 profit) - more than 4x Central's margin. | E11: Summary Tables - Section 3 / KPI Dashboard pie chart
A12: 8 | B12: Beginner | C12: Which customer segment spends the most? | D12: The Consumer segment drives the most revenue ($118,554, 49% of sales), followed by Corporate ($70,821) and Home Office ($51,755). | E12: Summary Tables - Section 4
A13: 9 | B13: Beginner | C13: Which segment is the most profitable (by margin)? | D13: Home Office customers convert best, with a 14.3% profit margin vs. 7.9% (Consumer) and just 2.8% (Corporate). | E13: Summary Tables - Section 4
A14: 10 | B14: Beginner | C14: How many unique customers are in the dataset? | D14: 362 unique customers placed 479 distinct orders (1,000 line items), averaging ~1.3 orders per customer. | E14: KPI Dashboard - Unique Customers card
A15: 11 | B15: Beginner | C15: What is the Average Order Value (AOV)? | D15: AOV = Total Sales / Distinct Orders = $241,131 / 479 = $503.40 per order. | E15: KPI Dashboard - AOV card
A16: 12 | B16: Beginner | C16: What is the average discount given? | D16: The average discount across all line items is 16.3%, though 46.3% of line items carry no discount at all. | E16: KPI Dashboard - Avg Discount card
... A45: 41 | B45: Advanced | C45: What is the single highest-leverage recommendation this dataset supports? | D45: Introducing a discount governance rule (e.g., manager approval above 20-30%) targeted at Furniture and Machines would address the largest, most concentrated source of profit erosion identified in the data. | E45: Cross-sheet synthesis - see Insights & Recommendations

Sheet Insights & Recommendations
A1: BUSINESS INSIGHTS & STRATEGIC RECOMMENDATIONS
A2: 25 data-driven insights, each paired with the recommendation it supports.
A4: # | B4: Insight | C4: Strategic Recommendation | D4: Impact / Priority
A5: 1 | B5: Technology is the company's largest revenue engine, generating $93,500 (38.8% of total sales) at a solid 8.6% margin. | C5: Protect and grow Technology's share of shelf/marketing spend; it is the category most able to absorb further growth investment without margin risk. | D5: High
A6: 2 | B6: Furniture is the only product category operating at a net loss overall (-2.2% margin, -$1,742), dragging down blended profitability. | C6: Commission a Furniture-specific pricing and cost review before the next planning cycle; do not scale Furniture marketing until margin is fixed. | D6: High
A7: 3 | B7: Within Furniture, Tables and Bookcases are individually loss-making, while Chairs remains profitable - the category's problem is concentrated, not universal. | C7: Ring-fence Tables and Bookcases for supplier renegotiation or SKU rationalization rather than treating all of Furniture as underperforming. | D7: High
A8: 4 | B8: Machines is the single worst sub-category company-wide (-$4,951 profit) despite meaningful sales ($32,622). | C8: Freeze further discount authority on Machines and review vendor cost basis; this SKU group alone offsets over a quarter of total company profit. | D8: High
A9: 5 | B9: Discount rate is the strongest observed driver of unprofitability: lines discounted above 40% average -63% margin, versus +31% for full-price lines. | C9: Introduce a discount-approval threshold (e.g., manager sign-off above 20-30%) enforced at the point of sale, prioritized for Furniture and Machines. | D9: High
A10: 6 | B10: Same Day shipping is the only delivery tier that is unprofitable overall (-$2,833), despite presumably carrying a premium price position. | C10: Re-price or restrict Same Day shipping eligibility (e.g., minimum order value or margin floor) so premium speed doesn't erode premium price. | D10: High
A11: 7 | B11: The West region combines the highest sales ($71,065) with the highest margin (15.4%) - it is the business's best-performing market on every axis measured. | C11: Use West as the template region: replicate its category mix, discount discipline, and channel approach when planning expansion in other regions. | D11: Medium
A12: 8 | B12: Central region ranks #2 in sales ($67,010) but has the weakest margin of any region (3.2%) - high volume is not translating into profit. | C12: Audit Central's discounting and cost-to-serve; investigate whether promotional intensity or fulfilment cost is eroding otherwise-healthy sales volume. | D12: High
A13: 9 | B13: Home Office customers convert best of any segment (14.3% margin) despite being the smallest segment by revenue ($51,755). | C13: Test increased marketing investment toward Home Office acquisition - it is currently under-weighted relative to its profitability. | D13: Medium
A14: 10 | B14: Corporate customers generate strong revenue ($70,821) but the weakest segment margin (2.8%), likely reflecting negotiated B2B discounting. | C14: Review Corporate account-level discount terms; consider tiered pricing based on order volume rather than a flat negotiated rate. | D14: Medium
A15: 11 | B15: Consumer is the largest segment by revenue (49% of sales) and sits at a moderate, sustainable 7.9% margin. | C15: Maintain current Consumer strategy as the revenue backbone; it needs stability and retention focus more than a margin overhaul. | D15: Monitor
A16: 12 | B16: Sales show clear seasonality: November-December alone account for 36% of annual revenue. | C16: Align inventory build, staffing, and cash-flow planning to a Q4-weighted calendar; under-stocking in Q4 carries outsized revenue risk. | D16: High
... A29: 25 | B29: Taken together, discounting - not category, region, or segment alone - is the common thread across every major loss driver identified (Furniture, Machines, Same Day, Central region). | C29: Elevate discount governance to a company-wide policy initiative; it is the single highest-leverage lever available in this dataset to close the profitability gap. | D29: High
